2025-09-23 18:28:41 - agent - ERROR - _select_tools:128 - Failed to select tools: 429 You exceeded your current quota, please check your plan and billing details. For more information on this error, head to: https://ai.google.dev/gemini-api/docs/rate-limits.
* Quota exceeded for metric: generativelanguage.googleapis.com/generate_content_free_tier_requests, limit: 50
Please retry in 17.258216754s. [violations {
  quota_metric: "generativelanguage.googleapis.com/generate_content_free_tier_requests"
  quota_id: "GenerateRequestsPerDayPerProjectPerModel-FreeTier"
  quota_dimensions {
    key: "model"
    value: "gemini-1.5-flash"
  }
  quota_dimensions {
    key: "location"
    value: "global"
  }
  quota_value: 50
}
, links {
  description: "Learn more about Gemini API quotas"
  url: "https://ai.google.dev/gemini-api/docs/rate-limits"
}
, retry_delay {
  seconds: 17
}
]
2025-09-23 18:28:42 - agent - ERROR - generate_plan:181 - Error during final plan generation: 429 You exceeded your current quota, please check your plan and billing details. For more information on this error, head to: https://ai.google.dev/gemini-api/docs/rate-limits.
* Quota exceeded for metric: generativelanguage.googleapis.com/generate_content_free_tier_requests, limit: 50
Please retry in 16.885559723s. [violations {
  quota_metric: "generativelanguage.googleapis.com/generate_content_free_tier_requests"
  quota_id: "GenerateRequestsPerDayPerProjectPerModel-FreeTier"
  quota_dimensions {
    key: "model"
    value: "gemini-1.5-flash"
  }
  quota_dimensions {
    key: "location"
    value: "global"
  }
  quota_value: 50
}
, links {
  description: "Learn more about Gemini API quotas"
  url: "https://ai.google.dev/gemini-api/docs/rate-limits"
}
, retry_delay {
  seconds: 16
}
]
Traceback (most recent call last):
  File "D:\Projects\Task Planner Agent\agent.py", line 176, in generate_plan
    response = self.model.generate_content(full_prompt)
  File "D:\Projects\Task Planner Agent\venv\Lib\site-packages\google\generativeai\generative_models.py", line 331, in generate_content
    response = self._client.generate_content(
        request,
        **request_options,
    )
  File "D:\Projects\Task Planner Agent\venv\Lib\site-packages\google\ai\generativelanguage_v1beta\services\generative_service\client.py", line 835, in generate_content
    response = rpc(
        request,
    ...<2 lines>...
        metadata=metadata,
    )
  File "D:\Projects\Task Planner Agent\venv\Lib\site-packages\google\api_core\gapic_v1\method.py", line 131, in __call__
    return wrapped_func(*args, **kwargs)
  File "D:\Projects\Task Planner Agent\venv\Lib\site-packages\google\api_core\retry\retry_unary.py", line 294, in retry_wrapped_func
    return retry_target(
        target,
    ...<3 lines>...
        on_error=on_error,
    )
  File "D:\Projects\Task Planner Agent\venv\Lib\site-packages\google\api_core\retry\retry_unary.py", line 156, in retry_target
    next_sleep = _retry_error_helper(
        exc,
    ...<6 lines>...
        timeout,
    )
  File "D:\Projects\Task Planner Agent\venv\Lib\site-packages\google\api_core\retry\retry_base.py", line 214, in _retry_error_helper
    raise final_exc from source_exc
  File "D:\Projects\Task Planner Agent\venv\Lib\site-packages\google\api_core\retry\retry_unary.py", line 147, in retry_target
    result = target()
  File "D:\Projects\Task Planner Agent\venv\Lib\site-packages\google\api_core\timeout.py", line 130, in func_with_timeout
    return func(*args, **kwargs)
  File "D:\Projects\Task Planner Agent\venv\Lib\site-packages\google\api_core\grpc_helpers.py", line 78, in error_remapped_callable
    raise exceptions.from_grpc_error(exc) from exc
google.api_core.exceptions.ResourceExhausted: 429 You exceeded your current quota, please check your plan and billing details. For more information on this error, head to: https://ai.google.dev/gemini-api/docs/rate-limits.
* Quota exceeded for metric: generativelanguage.googleapis.com/generate_content_free_tier_requests, limit: 50
Please retry in 16.885559723s. [violations {
  quota_metric: "generativelanguage.googleapis.com/generate_content_free_tier_requests"
  quota_id: "GenerateRequestsPerDayPerProjectPerModel-FreeTier"
  quota_dimensions {
    key: "model"
    value: "gemini-1.5-flash"
  }
  quota_dimensions {
    key: "location"
    value: "global"
  }
  quota_value: 50
}
, links {
  description: "Learn more about Gemini API quotas"
  url: "https://ai.google.dev/gemini-api/docs/rate-limits"
}
, retry_delay {
  seconds: 16
}
]

2025-09-23 18:28:42 - exceptions - ERROR - _log_error:91 - [UNEXPECTED_ERROR] Unexpected error: 429 You exceeded your current quota, please check your plan and billing details. For more information on this error, head to: https://ai.google.dev/gemini-api/docs/rate-limits.
* Quota exceeded for metric: generativelanguage.googleapis.com/generate_content_free_tier_requests, limit: 50
Please retry in 16.885559723s. [violations {
  quota_metric: "generativelanguage.googleapis.com/generate_content_free_tier_requests"
  quota_id: "GenerateRequestsPerDayPerProjectPerModel-FreeTier"
  quota_dimensions {
    key: "model"
    value: "gemini-1.5-flash"
  }
  quota_dimensions {
    key: "location"
    value: "global"
  }
  quota_value: 50
}
, links {
  description: "Learn more about Gemini API quotas"
  url: "https://ai.google.dev/gemini-api/docs/rate-limits"
}
, retry_delay {
  seconds: 16
}
] | Original: 429 You exceeded your current quota, please check your plan and billing details. For more information on this error, head to: https://ai.google.dev/gemini-api/docs/rate-limits.
* Quota exceeded for metric: generativelanguage.googleapis.com/generate_content_free_tier_requests, limit: 50
Please retry in 16.885559723s. [violations {
  quota_metric: "generativelanguage.googleapis.com/generate_content_free_tier_requests"
  quota_id: "GenerateRequestsPerDayPerProjectPerModel-FreeTier"
  quota_dimensions {
    key: "model"
    value: "gemini-1.5-flash"
  }
  quota_dimensions {
    key: "location"
    value: "global"
  }
  quota_value: 50
}
, links {
  description: "Learn more about Gemini API quotas"
  url: "https://ai.google.dev/gemini-api/docs/rate-limits"
}
, retry_delay {
  seconds: 16
}
]
2025-09-23 18:28:42 - exceptions - ERROR - _log_error:93 - Original error traceback: Traceback (most recent call last):
  File "D:\Projects\Task Planner Agent\main.py", line 98, in create_plan_endpoint
    plan_data = await agent.generate_plan(goal=plan_request.goal, start_date=plan_request.start_date)
                ^^^^^^^^^^^^^^^^^^^^^^^^^^^^^^^^^^^^^^^^^^^^^^^^^^^^^^^^^^^^^^^^^^^^^^^^^^^^^^^^^^^^^
  File "D:\Projects\Task Planner Agent\agent.py", line 176, in generate_plan
    response = self.model.generate_content(full_prompt)
  File "D:\Projects\Task Planner Agent\venv\Lib\site-packages\google\generativeai\generative_models.py", line 331, in generate_content
    response = self._client.generate_content(
        request,
        **request_options,
    )
  File "D:\Projects\Task Planner Agent\venv\Lib\site-packages\google\ai\generativelanguage_v1beta\services\generative_service\client.py", line 835, in generate_content
    response = rpc(
        request,
    ...<2 lines>...
        metadata=metadata,
    )
  File "D:\Projects\Task Planner Agent\venv\Lib\site-packages\google\api_core\gapic_v1\method.py", line 131, in __call__
    return wrapped_func(*args, **kwargs)
  File "D:\Projects\Task Planner Agent\venv\Lib\site-packages\google\api_core\retry\retry_unary.py", line 294, in retry_wrapped_func
    return retry_target(
        target,
    ...<3 lines>...
        on_error=on_error,
    )
  File "D:\Projects\Task Planner Agent\venv\Lib\site-packages\google\api_core\retry\retry_unary.py", line 156, in retry_target
    next_sleep = _retry_error_helper(
        exc,
    ...<6 lines>...
        timeout,
    )
  File "D:\Projects\Task Planner Agent\venv\Lib\site-packages\google\api_core\retry\retry_base.py", line 214, in _retry_error_helper
    raise final_exc from source_exc
  File "D:\Projects\Task Planner Agent\venv\Lib\site-packages\google\api_core\retry\retry_unary.py", line 147, in retry_target
    result = target()
  File "D:\Projects\Task Planner Agent\venv\Lib\site-packages\google\api_core\timeout.py", line 130, in func_with_timeout
    return func(*args, **kwargs)
  File "D:\Projects\Task Planner Agent\venv\Lib\site-packages\google\api_core\grpc_helpers.py", line 78, in error_remapped_callable
    raise exceptions.from_grpc_error(exc) from exc
google.api_core.exceptions.ResourceExhausted: 429 You exceeded your current quota, please check your plan and billing details. For more information on this error, head to: https://ai.google.dev/gemini-api/docs/rate-limits.
* Quota exceeded for metric: generativelanguage.googleapis.com/generate_content_free_tier_requests, limit: 50
Please retry in 16.885559723s. [violations {
  quota_metric: "generativelanguage.googleapis.com/generate_content_free_tier_requests"
  quota_id: "GenerateRequestsPerDayPerProjectPerModel-FreeTier"
  quota_dimensions {
    key: "model"
    value: "gemini-1.5-flash"
  }
  quota_dimensions {
    key: "location"
    value: "global"
  }
  quota_value: 50
}
, links {
  description: "Learn more about Gemini API quotas"
  url: "https://ai.google.dev/gemini-api/docs/rate-limits"
}
, retry_delay {
  seconds: 16
}
]

2025-09-23 18:28:42 - root - ERROR - create_plan_endpoint:118 - Failed to create plan: Unexpected error: 429 You exceeded your current quota, please check your plan and billing details. For more information on this error, head to: https://ai.google.dev/gemini-api/docs/rate-limits.
* Quota exceeded for metric: generativelanguage.googleapis.com/generate_content_free_tier_requests, limit: 50
Please retry in 16.885559723s. [violations {
  quota_metric: "generativelanguage.googleapis.com/generate_content_free_tier_requests"
  quota_id: "GenerateRequestsPerDayPerProjectPerModel-FreeTier"
  quota_dimensions {
    key: "model"
    value: "gemini-1.5-flash"
  }
  quota_dimensions {
    key: "location"
    value: "global"
  }
  quota_value: 50
}
, links {
  description: "Learn more about Gemini API quotas"
  url: "https://ai.google.dev/gemini-api/docs/rate-limits"
}
, retry_delay {
  seconds: 16
}
]
Traceback (most recent call last):
  File "D:\Projects\Task Planner Agent\main.py", line 98, in create_plan_endpoint
    plan_data = await agent.generate_plan(goal=plan_request.goal, start_date=plan_request.start_date)
                ^^^^^^^^^^^^^^^^^^^^^^^^^^^^^^^^^^^^^^^^^^^^^^^^^^^^^^^^^^^^^^^^^^^^^^^^^^^^^^^^^^^^^
  File "D:\Projects\Task Planner Agent\agent.py", line 176, in generate_plan
    response = self.model.generate_content(full_prompt)
  File "D:\Projects\Task Planner Agent\venv\Lib\site-packages\google\generativeai\generative_models.py", line 331, in generate_content
    response = self._client.generate_content(
        request,
        **request_options,
    )
  File "D:\Projects\Task Planner Agent\venv\Lib\site-packages\google\ai\generativelanguage_v1beta\services\generative_service\client.py", line 835, in generate_content
    response = rpc(
        request,
    ...<2 lines>...
        metadata=metadata,
    )
  File "D:\Projects\Task Planner Agent\venv\Lib\site-packages\google\api_core\gapic_v1\method.py", line 131, in __call__
    return wrapped_func(*args, **kwargs)
  File "D:\Projects\Task Planner Agent\venv\Lib\site-packages\google\api_core\retry\retry_unary.py", line 294, in retry_wrapped_func
    return retry_target(
        target,
    ...<3 lines>...
        on_error=on_error,
    )
  File "D:\Projects\Task Planner Agent\venv\Lib\site-packages\google\api_core\retry\retry_unary.py", line 156, in retry_target
    next_sleep = _retry_error_helper(
        exc,
    ...<6 lines>...
        timeout,
    )
  File "D:\Projects\Task Planner Agent\venv\Lib\site-packages\google\api_core\retry\retry_base.py", line 214, in _retry_error_helper
    raise final_exc from source_exc
  File "D:\Projects\Task Planner Agent\venv\Lib\site-packages\google\api_core\retry\retry_unary.py", line 147, in retry_target
    result = target()
  File "D:\Projects\Task Planner Agent\venv\Lib\site-packages\google\api_core\timeout.py", line 130, in func_with_timeout
    return func(*args, **kwargs)
  File "D:\Projects\Task Planner Agent\venv\Lib\site-packages\google\api_core\grpc_helpers.py", line 78, in error_remapped_callable
    raise exceptions.from_grpc_error(exc) from exc
google.api_core.exceptions.ResourceExhausted: 429 You exceeded your current quota, please check your plan and billing details. For more information on this error, head to: https://ai.google.dev/gemini-api/docs/rate-limits.
* Quota exceeded for metric: generativelanguage.googleapis.com/generate_content_free_tier_requests, limit: 50
Please retry in 16.885559723s. [violations {
  quota_metric: "generativelanguage.googleapis.com/generate_content_free_tier_requests"
  quota_id: "GenerateRequestsPerDayPerProjectPerModel-FreeTier"
  quota_dimensions {
    key: "model"
    value: "gemini-1.5-flash"
  }
  quota_dimensions {
    key: "location"
    value: "global"
  }
  quota_value: 50
}
, links {
  description: "Learn more about Gemini API quotas"
  url: "https://ai.google.dev/gemini-api/docs/rate-limits"
}
, retry_delay {
  seconds: 16
}
]

